apscheduler.scheduler - INFO - Scheduler started
telegram.ext.dispatcher - ERROR - No error handlers are registered, logging exception.
Traceback (most recent call last):
  File "C:\Users\питер\AppData\Local\Programs\Python\Python38\lib\site-packages\telegram\ext\dispatcher.py", line 555, in process_update
    handler.handle_update(update, self, check, context)
  File "C:\Users\питер\AppData\Local\Programs\Python\Python38\lib\site-packages\telegram\ext\handler.py", line 198, in handle_update
    return self.callback(update, context)
  File "c:/projects/learn-homework-1/8_ephem_bot.py", line 55, in planet
    if planet_name == ephem.planet_name(dt_now):
AttributeError: module 'ephem' has no attribute 'planet_name'
telegram.ext.dispatcher - ERROR - No error handlers are registered, logging exception.
Traceback (most recent call last):
  File "C:\Users\питер\AppData\Local\Programs\Python\Python38\lib\site-packages\telegram\ext\dispatcher.py", line 555, in process_update
    handler.handle_update(update, self, check, context)
  File "C:\Users\питер\AppData\Local\Programs\Python\Python38\lib\site-packages\telegram\ext\handler.py", line 198, in handle_update
    return self.callback(update, context)
  File "c:/projects/learn-homework-1/8_ephem_bot.py", line 53, in planet
    planet_name = update.message.text.split()[1]
IndexError: list index out of range
telegram.ext.dispatcher - ERROR - No error handlers are registered, logging exception.
Traceback (most recent call last):
  File "C:\Users\питер\AppData\Local\Programs\Python\Python38\lib\site-packages\telegram\ext\dispatcher.py", line 555, in process_update
    handler.handle_update(update, self, check, context)
  File "C:\Users\питер\AppData\Local\Programs\Python\Python38\lib\site-packages\telegram\ext\handler.py", line 198, in handle_update
    return self.callback(update, context)
  File "c:/projects/learn-homework-1/8_ephem_bot.py", line 55, in planet
    if planet_name == ephem.planet_name(dt_now):
AttributeError: module 'ephem' has no attribute 'planet_name'
apscheduler.scheduler - INFO - Scheduler started
telegram.ext.dispatcher - ERROR - No error handlers are registered, logging exception.
Traceback (most recent call last):
  File "C:\Users\питер\AppData\Local\Programs\Python\Python38\lib\site-packages\telegram\ext\dispatcher.py", line 555, in process_update
    handler.handle_update(update, self, check, context)
  File "C:\Users\питер\AppData\Local\Programs\Python\Python38\lib\site-packages\telegram\ext\handler.py", line 198, in handle_update
    return self.callback(update, context)
  File "c:/projects/learn-homework-1/8_ephem_bot.py", line 53, in planet
    planet_name = update.message.text.split()[1]
IndexError: list index out of range
telegram.ext.dispatcher - ERROR - No error handlers are registered, logging exception.
Traceback (most recent call last):
  File "C:\Users\питер\AppData\Local\Programs\Python\Python38\lib\site-packages\telegram\ext\dispatcher.py", line 555, in process_update
    handler.handle_update(update, self, check, context)
  File "C:\Users\питер\AppData\Local\Programs\Python\Python38\lib\site-packages\telegram\ext\handler.py", line 198, in handle_update
    return self.callback(update, context)
  File "c:/projects/learn-homework-1/8_ephem_bot.py", line 55, in planet
    if planet_name == ephem.planet_name(dt_now):
AttributeError: module 'ephem' has no attribute 'planet_name'
apscheduler.scheduler - INFO - Scheduler started
telegram.ext.dispatcher - ERROR - No error handlers are registered, logging exception.
Traceback (most recent call last):
  File "C:\Users\питер\AppData\Local\Programs\Python\Python38\lib\site-packages\telegram\ext\dispatcher.py", line 555, in process_update
    handler.handle_update(update, self, check, context)
  File "C:\Users\питер\AppData\Local\Programs\Python\Python38\lib\site-packages\telegram\ext\handler.py", line 198, in handle_update
    return self.callback(update, context)
  File "c:/projects/learn-homework-1/8_ephem_bot.py", line 53, in planet
    if planet_name in ephem.planet_name(dt_now):
AttributeError: module 'ephem' has no attribute 'planet_name'
telegram.vendor.ptb_urllib3.urllib3.connectionpool - WARNING - Retrying (Retry(total=2, connect=None, read=None, redirect=None)) after connection broken by 'NewConnectionError('<telegram.vendor.ptb_urllib3.urllib3.contrib.socks.SOCKSHTTPSConnection object at 0x00000000049EA700>: Failed to establish a new connection: [Errno 11004] getaddrinfo failed')': /bot1998874930:AAHSRnVPn6qTkHA0DGaLdtR17VQP4DxC0Ao/getUpdates
telegram.vendor.ptb_urllib3.urllib3.connectionpool - WARNING - Retrying (Retry(total=1, connect=None, read=None, redirect=None)) after connection broken by 'NewConnectionError('<telegram.vendor.ptb_urllib3.urllib3.contrib.socks.SOCKSHTTPSConnection object at 0x00000000049E2970>: Failed to establish a new connection: [Errno 11004] getaddrinfo failed')': /bot1998874930:AAHSRnVPn6qTkHA0DGaLdtR17VQP4DxC0Ao/getUpdates
telegram.vendor.ptb_urllib3.urllib3.connectionpool - WARNING - Retrying (Retry(total=0, connect=None, read=None, redirect=None)) after connection broken by 'NewConnectionError('<telegram.vendor.ptb_urllib3.urllib3.contrib.socks.SOCKSHTTPSConnection object at 0x00000000049EA760>: Failed to establish a new connection: [Errno 11004] getaddrinfo failed')': /bot1998874930:AAHSRnVPn6qTkHA0DGaLdtR17VQP4DxC0Ao/getUpdates
telegram.ext.updater - ERROR - Error while getting Updates: urllib3 HTTPError SOCKSHTTPSConnectionPool(host='api.telegram.org', port=443): Max retries exceeded with url: /bot1998874930:AAHSRnVPn6qTkHA0DGaLdtR17VQP4DxC0Ao/getUpdates (Caused by NewConnectionError('<telegram.vendor.ptb_urllib3.urllib3.contrib.socks.SOCKSHTTPSConnection object at 0x00000000049EA8B0>: Failed to establish a new connection: [Errno 11004] getaddrinfo failed'))
telegram.ext.dispatcher - ERROR - No error handlers are registered, logging exception.
Traceback (most recent call last):
  File "C:\Users\питер\AppData\Local\Programs\Python\Python38\lib\site-packages\telegram\vendor\ptb_urllib3\urllib3\contrib\socks.py", line 79, in _new_conn
    conn = socks.create_connection(
  File "C:\Users\питер\AppData\Local\Programs\Python\Python38\lib\site-packages\socks.py", line 180, in create_connection
    for r in socket.getaddrinfo(proxy_addr, proxy_port, 0, socket.SOCK_STREAM):
  File "C:\Users\питер\AppData\Local\Programs\Python\Python38\lib\socket.py", line 918, in getaddrinfo
    for res in _socket.getaddrinfo(host, port, family, type, proto, flags):
socket.gaierror: [Errno 11004] getaddrinfo failed

During handling of the above exception, another exception occurred:

Traceback (most recent call last):
  File "C:\Users\питер\AppData\Local\Programs\Python\Python38\lib\site-packages\telegram\vendor\ptb_urllib3\urllib3\connectionpool.py", line 614, in urlopen
    httplib_response = self._make_request(conn, method, url,
  File "C:\Users\питер\AppData\Local\Programs\Python\Python38\lib\site-packages\telegram\vendor\ptb_urllib3\urllib3\connectionpool.py", line 360, in _make_request
    self._validate_conn(conn)
  File "C:\Users\питер\AppData\Local\Programs\Python\Python38\lib\site-packages\telegram\vendor\ptb_urllib3\urllib3\connectionpool.py", line 857, in _validate_conn
    super(HTTPSConnectionPool, self)._validate_conn(conn)
  File "C:\Users\питер\AppData\Local\Programs\Python\Python38\lib\site-packages\telegram\vendor\ptb_urllib3\urllib3\connectionpool.py", line 289, in _validate_conn
    conn.connect()
  File "C:\Users\питер\AppData\Local\Programs\Python\Python38\lib\site-packages\telegram\vendor\ptb_urllib3\urllib3\connection.py", line 284, in connect
    conn = self._new_conn()
  File "C:\Users\питер\AppData\Local\Programs\Python\Python38\lib\site-packages\telegram\vendor\ptb_urllib3\urllib3\contrib\socks.py", line 119, in _new_conn
    raise NewConnectionError(
telegram.vendor.ptb_urllib3.urllib3.exceptions.NewConnectionError: <telegram.vendor.ptb_urllib3.urllib3.contrib.socks.SOCKSHTTPSConnection object at 0x00000000049EA8B0>: Failed to establish a new connection: [Errno 11004] getaddrinfo failed

During handling of the above exception, another exception occurred:

Traceback (most recent call last):
  File "C:\Users\питер\AppData\Local\Programs\Python\Python38\lib\site-packages\telegram\utils\request.py", line 259, in _request_wrapper
    resp = self._con_pool.request(*args, **kwargs)
  File "C:\Users\питер\AppData\Local\Programs\Python\Python38\lib\site-packages\telegram\vendor\ptb_urllib3\urllib3\request.py", line 68, in request
    return self.request_encode_body(method, url, fields=fields,
  File "C:\Users\питер\AppData\Local\Programs\Python\Python38\lib\site-packages\telegram\vendor\ptb_urllib3\urllib3\request.py", line 148, in request_encode_body
    return self.urlopen(method, url, **extra_kw)
  File "C:\Users\питер\AppData\Local\Programs\Python\Python38\lib\site-packages\telegram\vendor\ptb_urllib3\urllib3\poolmanager.py", line 244, in urlopen
    response = conn.urlopen(method, u.request_uri, **kw)
  File "C:\Users\питер\AppData\Local\Programs\Python\Python38\lib\site-packages\telegram\vendor\ptb_urllib3\urllib3\connectionpool.py", line 691, in urlopen
    return self.urlopen(method, url, body, headers, retries,
  File "C:\Users\питер\AppData\Local\Programs\Python\Python38\lib\site-packages\telegram\vendor\ptb_urllib3\urllib3\connectionpool.py", line 691, in urlopen
    return self.urlopen(method, url, body, headers, retries,
  File "C:\Users\питер\AppData\Local\Programs\Python\Python38\lib\site-packages\telegram\vendor\ptb_urllib3\urllib3\connectionpool.py", line 691, in urlopen
    return self.urlopen(method, url, body, headers, retries,
  File "C:\Users\питер\AppData\Local\Programs\Python\Python38\lib\site-packages\telegram\vendor\ptb_urllib3\urllib3\connectionpool.py", line 665, in urlopen
    retries = retries.increment(method, url, error=e, _pool=self,
  File "C:\Users\питер\AppData\Local\Programs\Python\Python38\lib\site-packages\telegram\vendor\ptb_urllib3\urllib3\util\retry.py", line 376, in increment
    raise MaxRetryError(_pool, url, error or ResponseError(cause))
telegram.vendor.ptb_urllib3.urllib3.exceptions.MaxRetryError: SOCKSHTTPSConnectionPool(host='api.telegram.org', port=443): Max retries exceeded with url: /bot1998874930:AAHSRnVPn6qTkHA0DGaLdtR17VQP4DxC0Ao/getUpdates (Caused by NewConnectionError('<telegram.vendor.ptb_urllib3.urllib3.contrib.socks.SOCKSHTTPSConnection object at 0x00000000049EA8B0>: Failed to establish a new connection: [Errno 11004] getaddrinfo failed'))

The above exception was the direct cause of the following exception:

Traceback (most recent call last):
  File "C:\Users\питер\AppData\Local\Programs\Python\Python38\lib\site-packages\telegram\ext\updater.py", line 646, in _network_loop_retry
    if not action_cb():
  File "C:\Users\питер\AppData\Local\Programs\Python\Python38\lib\site-packages\telegram\ext\updater.py", line 597, in polling_action_cb
    updates = self.bot.get_updates(
  File "C:\Users\питер\AppData\Local\Programs\Python\Python38\lib\site-packages\telegram\ext\extbot.py", line 222, in get_updates
    updates = super().get_updates(
  File "C:\Users\питер\AppData\Local\Programs\Python\Python38\lib\site-packages\telegram\bot.py", line 130, in decorator
    result = func(*args, **kwargs)
  File "C:\Users\питер\AppData\Local\Programs\Python\Python38\lib\site-packages\telegram\bot.py", line 2861, in get_updates
    self._post(
  File "C:\Users\питер\AppData\Local\Programs\Python\Python38\lib\site-packages\telegram\bot.py", line 295, in _post
    return self.request.post(
  File "C:\Users\питер\AppData\Local\Programs\Python\Python38\lib\site-packages\telegram\utils\request.py", line 356, in post
    result = self._request_wrapper(
  File "C:\Users\питер\AppData\Local\Programs\Python\Python38\lib\site-packages\telegram\utils\request.py", line 265, in _request_wrapper
    raise NetworkError(f'urllib3 HTTPError {error}') from error
telegram.error.NetworkError: urllib3 HTTPError SOCKSHTTPSConnectionPool(host='api.telegram.org', port=443): Max retries exceeded with url: /bot1998874930:AAHSRnVPn6qTkHA0DGaLdtR17VQP4DxC0Ao/getUpdates (Caused by NewConnectionError('<telegram.vendor.ptb_urllib3.urllib3.contrib.socks.SOCKSHTTPSConnection object at 0x00000000049EA8B0>: Failed to establish a new connection: [Errno 11004] getaddrinfo failed'))
telegram.vendor.ptb_urllib3.urllib3.connectionpool - WARNING - Retrying (Retry(total=2, connect=None, read=None, redirect=None)) after connection broken by 'NewConnectionError('<telegram.vendor.ptb_urllib3.urllib3.contrib.socks.SOCKSHTTPSConnection object at 0x00000000049EACA0>: Failed to establish a new connection: [Errno 11004] getaddrinfo failed')': /bot1998874930:AAHSRnVPn6qTkHA0DGaLdtR17VQP4DxC0Ao/getUpdates
telegram.vendor.ptb_urllib3.urllib3.connectionpool - WARNING - Retrying (Retry(total=1, connect=None, read=None, redirect=None)) after connection broken by 'NewConnectionError('<telegram.vendor.ptb_urllib3.urllib3.contrib.socks.SOCKSHTTPSConnection object at 0x00000000049EAE20>: Failed to establish a new connection: [Errno 11004] getaddrinfo failed')': /bot1998874930:AAHSRnVPn6qTkHA0DGaLdtR17VQP4DxC0Ao/getUpdates
telegram.vendor.ptb_urllib3.urllib3.connectionpool - WARNING - Retrying (Retry(total=0, connect=None, read=None, redirect=None)) after connection broken by 'NewConnectionError('<telegram.vendor.ptb_urllib3.urllib3.contrib.socks.SOCKSHTTPSConnection object at 0x00000000049EAF70>: Failed to establish a new connection: [Errno 11004] getaddrinfo failed')': /bot1998874930:AAHSRnVPn6qTkHA0DGaLdtR17VQP4DxC0Ao/getUpdates
telegram.ext.updater - ERROR - Error while getting Updates: urllib3 HTTPError SOCKSHTTPSConnectionPool(host='api.telegram.org', port=443): Max retries exceeded with url: /bot1998874930:AAHSRnVPn6qTkHA0DGaLdtR17VQP4DxC0Ao/getUpdates (Caused by NewConnectionError('<telegram.vendor.ptb_urllib3.urllib3.contrib.socks.SOCKSHTTPSConnection object at 0x0000000004D0A100>: Failed to establish a new connection: [Errno 11004] getaddrinfo failed'))
telegram.ext.dispatcher - ERROR - No error handlers are registered, logging exception.
Traceback (most recent call last):
  File "C:\Users\питер\AppData\Local\Programs\Python\Python38\lib\site-packages\telegram\vendor\ptb_urllib3\urllib3\contrib\socks.py", line 79, in _new_conn
    conn = socks.create_connection(
  File "C:\Users\питер\AppData\Local\Programs\Python\Python38\lib\site-packages\socks.py", line 180, in create_connection
    for r in socket.getaddrinfo(proxy_addr, proxy_port, 0, socket.SOCK_STREAM):
  File "C:\Users\питер\AppData\Local\Programs\Python\Python38\lib\socket.py", line 918, in getaddrinfo
    for res in _socket.getaddrinfo(host, port, family, type, proto, flags):
socket.gaierror: [Errno 11004] getaddrinfo failed

During handling of the above exception, another exception occurred:

Traceback (most recent call last):
  File "C:\Users\питер\AppData\Local\Programs\Python\Python38\lib\site-packages\telegram\vendor\ptb_urllib3\urllib3\connectionpool.py", line 614, in urlopen
    httplib_response = self._make_request(conn, method, url,
  File "C:\Users\питер\AppData\Local\Programs\Python\Python38\lib\site-packages\telegram\vendor\ptb_urllib3\urllib3\connectionpool.py", line 360, in _make_request
    self._validate_conn(conn)
  File "C:\Users\питер\AppData\Local\Programs\Python\Python38\lib\site-packages\telegram\vendor\ptb_urllib3\urllib3\connectionpool.py", line 857, in _validate_conn
    super(HTTPSConnectionPool, self)._validate_conn(conn)
  File "C:\Users\питер\AppData\Local\Programs\Python\Python38\lib\site-packages\telegram\vendor\ptb_urllib3\urllib3\connectionpool.py", line 289, in _validate_conn
    conn.connect()
  File "C:\Users\питер\AppData\Local\Programs\Python\Python38\lib\site-packages\telegram\vendor\ptb_urllib3\urllib3\connection.py", line 284, in connect
    conn = self._new_conn()
  File "C:\Users\питер\AppData\Local\Programs\Python\Python38\lib\site-packages\telegram\vendor\ptb_urllib3\urllib3\contrib\socks.py", line 119, in _new_conn
    raise NewConnectionError(
telegram.vendor.ptb_urllib3.urllib3.exceptions.NewConnectionError: <telegram.vendor.ptb_urllib3.urllib3.contrib.socks.SOCKSHTTPSConnection object at 0x0000000004D0A100>: Failed to establish a new connection: [Errno 11004] getaddrinfo failed

During handling of the above exception, another exception occurred:

Traceback (most recent call last):
  File "C:\Users\питер\AppData\Local\Programs\Python\Python38\lib\site-packages\telegram\utils\request.py", line 259, in _request_wrapper
    resp = self._con_pool.request(*args, **kwargs)
  File "C:\Users\питер\AppData\Local\Programs\Python\Python38\lib\site-packages\telegram\vendor\ptb_urllib3\urllib3\request.py", line 68, in request
    return self.request_encode_body(method, url, fields=fields,
  File "C:\Users\питер\AppData\Local\Programs\Python\Python38\lib\site-packages\telegram\vendor\ptb_urllib3\urllib3\request.py", line 148, in request_encode_body
    return self.urlopen(method, url, **extra_kw)
  File "C:\Users\питер\AppData\Local\Programs\Python\Python38\lib\site-packages\telegram\vendor\ptb_urllib3\urllib3\poolmanager.py", line 244, in urlopen
    response = conn.urlopen(method, u.request_uri, **kw)
  File "C:\Users\питер\AppData\Local\Programs\Python\Python38\lib\site-packages\telegram\vendor\ptb_urllib3\urllib3\connectionpool.py", line 691, in urlopen
    return self.urlopen(method, url, body, headers, retries,
  File "C:\Users\питер\AppData\Local\Programs\Python\Python38\lib\site-packages\telegram\vendor\ptb_urllib3\urllib3\connectionpool.py", line 691, in urlopen
    return self.urlopen(method, url, body, headers, retries,
  File "C:\Users\питер\AppData\Local\Programs\Python\Python38\lib\site-packages\telegram\vendor\ptb_urllib3\urllib3\connectionpool.py", line 691, in urlopen
    return self.urlopen(method, url, body, headers, retries,
  File "C:\Users\питер\AppData\Local\Programs\Python\Python38\lib\site-packages\telegram\vendor\ptb_urllib3\urllib3\connectionpool.py", line 665, in urlopen
    retries = retries.increment(method, url, error=e, _pool=self,
  File "C:\Users\питер\AppData\Local\Programs\Python\Python38\lib\site-packages\telegram\vendor\ptb_urllib3\urllib3\util\retry.py", line 376, in increment
    raise MaxRetryError(_pool, url, error or ResponseError(cause))
telegram.vendor.ptb_urllib3.urllib3.exceptions.MaxRetryError: SOCKSHTTPSConnectionPool(host='api.telegram.org', port=443): Max retries exceeded with url: /bot1998874930:AAHSRnVPn6qTkHA0DGaLdtR17VQP4DxC0Ao/getUpdates (Caused by NewConnectionError('<telegram.vendor.ptb_urllib3.urllib3.contrib.socks.SOCKSHTTPSConnection object at 0x0000000004D0A100>: Failed to establish a new connection: [Errno 11004] getaddrinfo failed'))

The above exception was the direct cause of the following exception:

Traceback (most recent call last):
  File "C:\Users\питер\AppData\Local\Programs\Python\Python38\lib\site-packages\telegram\ext\updater.py", line 646, in _network_loop_retry
    if not action_cb():
  File "C:\Users\питер\AppData\Local\Programs\Python\Python38\lib\site-packages\telegram\ext\updater.py", line 597, in polling_action_cb
    updates = self.bot.get_updates(
  File "C:\Users\питер\AppData\Local\Programs\Python\Python38\lib\site-packages\telegram\ext\extbot.py", line 222, in get_updates
    updates = super().get_updates(
  File "C:\Users\питер\AppData\Local\Programs\Python\Python38\lib\site-packages\telegram\bot.py", line 130, in decorator
    result = func(*args, **kwargs)
  File "C:\Users\питер\AppData\Local\Programs\Python\Python38\lib\site-packages\telegram\bot.py", line 2861, in get_updates
    self._post(
  File "C:\Users\питер\AppData\Local\Programs\Python\Python38\lib\site-packages\telegram\bot.py", line 295, in _post
    return self.request.post(
  File "C:\Users\питер\AppData\Local\Programs\Python\Python38\lib\site-packages\telegram\utils\request.py", line 356, in post
    result = self._request_wrapper(
  File "C:\Users\питер\AppData\Local\Programs\Python\Python38\lib\site-packages\telegram\utils\request.py", line 265, in _request_wrapper
    raise NetworkError(f'urllib3 HTTPError {error}') from error
telegram.error.NetworkError: urllib3 HTTPError SOCKSHTTPSConnectionPool(host='api.telegram.org', port=443): Max retries exceeded with url: /bot1998874930:AAHSRnVPn6qTkHA0DGaLdtR17VQP4DxC0Ao/getUpdates (Caused by NewConnectionError('<telegram.vendor.ptb_urllib3.urllib3.contrib.socks.SOCKSHTTPSConnection object at 0x0000000004D0A100>: Failed to establish a new connection: [Errno 11004] getaddrinfo failed'))
telegram.vendor.ptb_urllib3.urllib3.connectionpool - WARNING - Retrying (Retry(total=2, connect=None, read=None, redirect=None)) after connection broken by 'NewConnectionError('<telegram.vendor.ptb_urllib3.urllib3.contrib.socks.SOCKSHTTPSConnection object at 0x00000000049EA9D0>: Failed to establish a new connection: [Errno 11004] getaddrinfo failed')': /bot1998874930:AAHSRnVPn6qTkHA0DGaLdtR17VQP4DxC0Ao/getUpdates
telegram.vendor.ptb_urllib3.urllib3.connectionpool - WARNING - Retrying (Retry(total=1, connect=None, read=None, redirect=None)) after connection broken by 'NewConnectionError('<telegram.vendor.ptb_urllib3.urllib3.contrib.socks.SOCKSHTTPSConnection object at 0x0000000004D0A2B0>: Failed to establish a new connection: [Errno 11004] getaddrinfo failed')': /bot1998874930:AAHSRnVPn6qTkHA0DGaLdtR17VQP4DxC0Ao/getUpdates
telegram.vendor.ptb_urllib3.urllib3.connectionpool - WARNING - Retrying (Retry(total=0, connect=None, read=None, redirect=None)) after connection broken by 'NewConnectionError('<telegram.vendor.ptb_urllib3.urllib3.contrib.socks.SOCKSHTTPSConnection object at 0x0000000004D0A400>: Failed to establish a new connection: [Errno 11004] getaddrinfo failed')': /bot1998874930:AAHSRnVPn6qTkHA0DGaLdtR17VQP4DxC0Ao/getUpdates
telegram.ext.updater - ERROR - Error while getting Updates: urllib3 HTTPError SOCKSHTTPSConnectionPool(host='api.telegram.org', port=443): Max retries exceeded with url: /bot1998874930:AAHSRnVPn6qTkHA0DGaLdtR17VQP4DxC0Ao/getUpdates (Caused by NewConnectionError('<telegram.vendor.ptb_urllib3.urllib3.contrib.socks.SOCKSHTTPSConnection object at 0x0000000004D0A550>: Failed to establish a new connection: [Errno 11004] getaddrinfo failed'))
telegram.ext.dispatcher - ERROR - No error handlers are registered, logging exception.
Traceback (most recent call last):
  File "C:\Users\питер\AppData\Local\Programs\Python\Python38\lib\site-packages\telegram\vendor\ptb_urllib3\urllib3\contrib\socks.py", line 79, in _new_conn
    conn = socks.create_connection(
  File "C:\Users\питер\AppData\Local\Programs\Python\Python38\lib\site-packages\socks.py", line 180, in create_connection
    for r in socket.getaddrinfo(proxy_addr, proxy_port, 0, socket.SOCK_STREAM):
  File "C:\Users\питер\AppData\Local\Programs\Python\Python38\lib\socket.py", line 918, in getaddrinfo
    for res in _socket.getaddrinfo(host, port, family, type, proto, flags):
socket.gaierror: [Errno 11004] getaddrinfo failed

During handling of the above exception, another exception occurred:

Traceback (most recent call last):
  File "C:\Users\питер\AppData\Local\Programs\Python\Python38\lib\site-packages\telegram\vendor\ptb_urllib3\urllib3\connectionpool.py", line 614, in urlopen
    httplib_response = self._make_request(conn, method, url,
  File "C:\Users\питер\AppData\Local\Programs\Python\Python38\lib\site-packages\telegram\vendor\ptb_urllib3\urllib3\connectionpool.py", line 360, in _make_request
    self._validate_conn(conn)
  File "C:\Users\питер\AppData\Local\Programs\Python\Python38\lib\site-packages\telegram\vendor\ptb_urllib3\urllib3\connectionpool.py", line 857, in _validate_conn
    super(HTTPSConnectionPool, self)._validate_conn(conn)
  File "C:\Users\питер\AppData\Local\Programs\Python\Python38\lib\site-packages\telegram\vendor\ptb_urllib3\urllib3\connectionpool.py", line 289, in _validate_conn
    conn.connect()
  File "C:\Users\питер\AppData\Local\Programs\Python\Python38\lib\site-packages\telegram\vendor\ptb_urllib3\urllib3\connection.py", line 284, in connect
    conn = self._new_conn()
  File "C:\Users\питер\AppData\Local\Programs\Python\Python38\lib\site-packages\telegram\vendor\ptb_urllib3\urllib3\contrib\socks.py", line 119, in _new_conn
    raise NewConnectionError(
telegram.vendor.ptb_urllib3.urllib3.exceptions.NewConnectionError: <telegram.vendor.ptb_urllib3.urllib3.contrib.socks.SOCKSHTTPSConnection object at 0x0000000004D0A550>: Failed to establish a new connection: [Errno 11004] getaddrinfo failed

During handling of the above exception, another exception occurred:

Traceback (most recent call last):
  File "C:\Users\питер\AppData\Local\Programs\Python\Python38\lib\site-packages\telegram\utils\request.py", line 259, in _request_wrapper
    resp = self._con_pool.request(*args, **kwargs)
  File "C:\Users\питер\AppData\Local\Programs\Python\Python38\lib\site-packages\telegram\vendor\ptb_urllib3\urllib3\request.py", line 68, in request
    return self.request_encode_body(method, url, fields=fields,
  File "C:\Users\питер\AppData\Local\Programs\Python\Python38\lib\site-packages\telegram\vendor\ptb_urllib3\urllib3\request.py", line 148, in request_encode_body
    return self.urlopen(method, url, **extra_kw)
  File "C:\Users\питер\AppData\Local\Programs\Python\Python38\lib\site-packages\telegram\vendor\ptb_urllib3\urllib3\poolmanager.py", line 244, in urlopen
    response = conn.urlopen(method, u.request_uri, **kw)
  File "C:\Users\питер\AppData\Local\Programs\Python\Python38\lib\site-packages\telegram\vendor\ptb_urllib3\urllib3\connectionpool.py", line 691, in urlopen
    return self.urlopen(method, url, body, headers, retries,
  File "C:\Users\питер\AppData\Local\Programs\Python\Python38\lib\site-packages\telegram\vendor\ptb_urllib3\urllib3\connectionpool.py", line 691, in urlopen
    return self.urlopen(method, url, body, headers, retries,
  File "C:\Users\питер\AppData\Local\Programs\Python\Python38\lib\site-packages\telegram\vendor\ptb_urllib3\urllib3\connectionpool.py", line 691, in urlopen
    return self.urlopen(method, url, body, headers, retries,
  File "C:\Users\питер\AppData\Local\Programs\Python\Python38\lib\site-packages\telegram\vendor\ptb_urllib3\urllib3\connectionpool.py", line 665, in urlopen
    retries = retries.increment(method, url, error=e, _pool=self,
  File "C:\Users\питер\AppData\Local\Programs\Python\Python38\lib\site-packages\telegram\vendor\ptb_urllib3\urllib3\util\retry.py", line 376, in increment
    raise MaxRetryError(_pool, url, error or ResponseError(cause))
telegram.vendor.ptb_urllib3.urllib3.exceptions.MaxRetryError: SOCKSHTTPSConnectionPool(host='api.telegram.org', port=443): Max retries exceeded with url: /bot1998874930:AAHSRnVPn6qTkHA0DGaLdtR17VQP4DxC0Ao/getUpdates (Caused by NewConnectionError('<telegram.vendor.ptb_urllib3.urllib3.contrib.socks.SOCKSHTTPSConnection object at 0x0000000004D0A550>: Failed to establish a new connection: [Errno 11004] getaddrinfo failed'))

The above exception was the direct cause of the following exception:

Traceback (most recent call last):
  File "C:\Users\питер\AppData\Local\Programs\Python\Python38\lib\site-packages\telegram\ext\updater.py", line 646, in _network_loop_retry
    if not action_cb():
  File "C:\Users\питер\AppData\Local\Programs\Python\Python38\lib\site-packages\telegram\ext\updater.py", line 597, in polling_action_cb
    updates = self.bot.get_updates(
  File "C:\Users\питер\AppData\Local\Programs\Python\Python38\lib\site-packages\telegram\ext\extbot.py", line 222, in get_updates
    updates = super().get_updates(
  File "C:\Users\питер\AppData\Local\Programs\Python\Python38\lib\site-packages\telegram\bot.py", line 130, in decorator
    result = func(*args, **kwargs)
  File "C:\Users\питер\AppData\Local\Programs\Python\Python38\lib\site-packages\telegram\bot.py", line 2861, in get_updates
    self._post(
  File "C:\Users\питер\AppData\Local\Programs\Python\Python38\lib\site-packages\telegram\bot.py", line 295, in _post
    return self.request.post(
  File "C:\Users\питер\AppData\Local\Programs\Python\Python38\lib\site-packages\telegram\utils\request.py", line 356, in post
    result = self._request_wrapper(
  File "C:\Users\питер\AppData\Local\Programs\Python\Python38\lib\site-packages\telegram\utils\request.py", line 265, in _request_wrapper
    raise NetworkError(f'urllib3 HTTPError {error}') from error
telegram.error.NetworkError: urllib3 HTTPError SOCKSHTTPSConnectionPool(host='api.telegram.org', port=443): Max retries exceeded with url: /bot1998874930:AAHSRnVPn6qTkHA0DGaLdtR17VQP4DxC0Ao/getUpdates (Caused by NewConnectionError('<telegram.vendor.ptb_urllib3.urllib3.contrib.socks.SOCKSHTTPSConnection object at 0x0000000004D0A550>: Failed to establish a new connection: [Errno 11004] getaddrinfo failed'))
telegram.vendor.ptb_urllib3.urllib3.connectionpool - WARNING - Retrying (Retry(total=2, connect=None, read=None, redirect=None)) after connection broken by 'NewConnectionError('<telegram.vendor.ptb_urllib3.urllib3.contrib.socks.SOCKSHTTPSConnection object at 0x0000000004D0A100>: Failed to establish a new connection: [Errno 11004] getaddrinfo failed')': /bot1998874930:AAHSRnVPn6qTkHA0DGaLdtR17VQP4DxC0Ao/getUpdates
telegram.vendor.ptb_urllib3.urllib3.connectionpool - WARNING - Retrying (Retry(total=1, connect=None, read=None, redirect=None)) after connection broken by 'NewConnectionError('<telegram.vendor.ptb_urllib3.urllib3.contrib.socks.SOCKSHTTPSConnection object at 0x0000000004D0A700>: Failed to establish a new connection: [Errno 11004] getaddrinfo failed')': /bot1998874930:AAHSRnVPn6qTkHA0DGaLdtR17VQP4DxC0Ao/getUpdates
telegram.vendor.ptb_urllib3.urllib3.connectionpool - WARNING - Retrying (Retry(total=0, connect=None, read=None, redirect=None)) after connection broken by 'NewConnectionError('<telegram.vendor.ptb_urllib3.urllib3.contrib.socks.SOCKSHTTPSConnection object at 0x0000000004D0A850>: Failed to establish a new connection: [Errno 11004] getaddrinfo failed')': /bot1998874930:AAHSRnVPn6qTkHA0DGaLdtR17VQP4DxC0Ao/getUpdates
telegram.ext.updater - ERROR - Error while getting Updates: urllib3 HTTPError SOCKSHTTPSConnectionPool(host='api.telegram.org', port=443): Max retries exceeded with url: /bot1998874930:AAHSRnVPn6qTkHA0DGaLdtR17VQP4DxC0Ao/getUpdates (Caused by NewConnectionError('<telegram.vendor.ptb_urllib3.urllib3.contrib.socks.SOCKSHTTPSConnection object at 0x0000000004D0A9A0>: Failed to establish a new connection: [Errno 11004] getaddrinfo failed'))
telegram.ext.dispatcher - ERROR - No error handlers are registered, logging exception.
Traceback (most recent call last):
  File "C:\Users\питер\AppData\Local\Programs\Python\Python38\lib\site-packages\telegram\vendor\ptb_urllib3\urllib3\contrib\socks.py", line 79, in _new_conn
    conn = socks.create_connection(
  File "C:\Users\питер\AppData\Local\Programs\Python\Python38\lib\site-packages\socks.py", line 180, in create_connection
    for r in socket.getaddrinfo(proxy_addr, proxy_port, 0, socket.SOCK_STREAM):
  File "C:\Users\питер\AppData\Local\Programs\Python\Python38\lib\socket.py", line 918, in getaddrinfo
    for res in _socket.getaddrinfo(host, port, family, type, proto, flags):
socket.gaierror: [Errno 11004] getaddrinfo failed

During handling of the above exception, another exception occurred:

Traceback (most recent call last):
  File "C:\Users\питер\AppData\Local\Programs\Python\Python38\lib\site-packages\telegram\vendor\ptb_urllib3\urllib3\connectionpool.py", line 614, in urlopen
    httplib_response = self._make_request(conn, method, url,
  File "C:\Users\питер\AppData\Local\Programs\Python\Python38\lib\site-packages\telegram\vendor\ptb_urllib3\urllib3\connectionpool.py", line 360, in _make_request
    self._validate_conn(conn)
  File "C:\Users\питер\AppData\Local\Programs\Python\Python38\lib\site-packages\telegram\vendor\ptb_urllib3\urllib3\connectionpool.py", line 857, in _validate_conn
    super(HTTPSConnectionPool, self)._validate_conn(conn)
  File "C:\Users\питер\AppData\Local\Programs\Python\Python38\lib\site-packages\telegram\vendor\ptb_urllib3\urllib3\connectionpool.py", line 289, in _validate_conn
    conn.connect()
  File "C:\Users\питер\AppData\Local\Programs\Python\Python38\lib\site-packages\telegram\vendor\ptb_urllib3\urllib3\connection.py", line 284, in connect
    conn = self._new_conn()
  File "C:\Users\питер\AppData\Local\Programs\Python\Python38\lib\site-packages\telegram\vendor\ptb_urllib3\urllib3\contrib\socks.py", line 119, in _new_conn
    raise NewConnectionError(
telegram.vendor.ptb_urllib3.urllib3.exceptions.NewConnectionError: <telegram.vendor.ptb_urllib3.urllib3.contrib.socks.SOCKSHTTPSConnection object at 0x0000000004D0A9A0>: Failed to establish a new connection: [Errno 11004] getaddrinfo failed

During handling of the above exception, another exception occurred:

Traceback (most recent call last):
  File "C:\Users\питер\AppData\Local\Programs\Python\Python38\lib\site-packages\telegram\utils\request.py", line 259, in _request_wrapper
    resp = self._con_pool.request(*args, **kwargs)
  File "C:\Users\питер\AppData\Local\Programs\Python\Python38\lib\site-packages\telegram\vendor\ptb_urllib3\urllib3\request.py", line 68, in request
    return self.request_encode_body(method, url, fields=fields,
  File "C:\Users\питер\AppData\Local\Programs\Python\Python38\lib\site-packages\telegram\vendor\ptb_urllib3\urllib3\request.py", line 148, in request_encode_body
    return self.urlopen(method, url, **extra_kw)
  File "C:\Users\питер\AppData\Local\Programs\Python\Python38\lib\site-packages\telegram\vendor\ptb_urllib3\urllib3\poolmanager.py", line 244, in urlopen
    response = conn.urlopen(method, u.request_uri, **kw)
  File "C:\Users\питер\AppData\Local\Programs\Python\Python38\lib\site-packages\telegram\vendor\ptb_urllib3\urllib3\connectionpool.py", line 691, in urlopen
    return self.urlopen(method, url, body, headers, retries,
  File "C:\Users\питер\AppData\Local\Programs\Python\Python38\lib\site-packages\telegram\vendor\ptb_urllib3\urllib3\connectionpool.py", line 691, in urlopen
    return self.urlopen(method, url, body, headers, retries,
  File "C:\Users\питер\AppData\Local\Programs\Python\Python38\lib\site-packages\telegram\vendor\ptb_urllib3\urllib3\connectionpool.py", line 691, in urlopen
    return self.urlopen(method, url, body, headers, retries,
  File "C:\Users\питер\AppData\Local\Programs\Python\Python38\lib\site-packages\telegram\vendor\ptb_urllib3\urllib3\connectionpool.py", line 665, in urlopen
    retries = retries.increment(method, url, error=e, _pool=self,
  File "C:\Users\питер\AppData\Local\Programs\Python\Python38\lib\site-packages\telegram\vendor\ptb_urllib3\urllib3\util\retry.py", line 376, in increment
    raise MaxRetryError(_pool, url, error or ResponseError(cause))
telegram.vendor.ptb_urllib3.urllib3.exceptions.MaxRetryError: SOCKSHTTPSConnectionPool(host='api.telegram.org', port=443): Max retries exceeded with url: /bot1998874930:AAHSRnVPn6qTkHA0DGaLdtR17VQP4DxC0Ao/getUpdates (Caused by NewConnectionError('<telegram.vendor.ptb_urllib3.urllib3.contrib.socks.SOCKSHTTPSConnection object at 0x0000000004D0A9A0>: Failed to establish a new connection: [Errno 11004] getaddrinfo failed'))

The above exception was the direct cause of the following exception:

Traceback (most recent call last):
  File "C:\Users\питер\AppData\Local\Programs\Python\Python38\lib\site-packages\telegram\ext\updater.py", line 646, in _network_loop_retry
    if not action_cb():
  File "C:\Users\питер\AppData\Local\Programs\Python\Python38\lib\site-packages\telegram\ext\updater.py", line 597, in polling_action_cb
    updates = self.bot.get_updates(
  File "C:\Users\питер\AppData\Local\Programs\Python\Python38\lib\site-packages\telegram\ext\extbot.py", line 222, in get_updates
    updates = super().get_updates(
  File "C:\Users\питер\AppData\Local\Programs\Python\Python38\lib\site-packages\telegram\bot.py", line 130, in decorator
    result = func(*args, **kwargs)
  File "C:\Users\питер\AppData\Local\Programs\Python\Python38\lib\site-packages\telegram\bot.py", line 2861, in get_updates
    self._post(
  File "C:\Users\питер\AppData\Local\Programs\Python\Python38\lib\site-packages\telegram\bot.py", line 295, in _post
    return self.request.post(
  File "C:\Users\питер\AppData\Local\Programs\Python\Python38\lib\site-packages\telegram\utils\request.py", line 356, in post
    result = self._request_wrapper(
  File "C:\Users\питер\AppData\Local\Programs\Python\Python38\lib\site-packages\telegram\utils\request.py", line 265, in _request_wrapper
    raise NetworkError(f'urllib3 HTTPError {error}') from error
telegram.error.NetworkError: urllib3 HTTPError SOCKSHTTPSConnectionPool(host='api.telegram.org', port=443): Max retries exceeded with url: /bot1998874930:AAHSRnVPn6qTkHA0DGaLdtR17VQP4DxC0Ao/getUpdates (Caused by NewConnectionError('<telegram.vendor.ptb_urllib3.urllib3.contrib.socks.SOCKSHTTPSConnection object at 0x0000000004D0A9A0>: Failed to establish a new connection: [Errno 11004] getaddrinfo failed'))
telegram.vendor.ptb_urllib3.urllib3.connectionpool - WARNING - Retrying (Retry(total=2, connect=None, read=None, redirect=None)) after connection broken by 'NewConnectionError('<telegram.vendor.ptb_urllib3.urllib3.contrib.socks.SOCKSHTTPSConnection object at 0x0000000004D0A5E0>: Failed to establish a new connection: [Errno 11004] getaddrinfo failed')': /bot1998874930:AAHSRnVPn6qTkHA0DGaLdtR17VQP4DxC0Ao/getUpdates
telegram.vendor.ptb_urllib3.urllib3.connectionpool - WARNING - Retrying (Retry(total=1, connect=None, read=None, redirect=None)) after connection broken by 'NewConnectionError('<telegram.vendor.ptb_urllib3.urllib3.contrib.socks.SOCKSHTTPSConnection object at 0x0000000004D0AB50>: Failed to establish a new connection: [Errno 11004] getaddrinfo failed')': /bot1998874930:AAHSRnVPn6qTkHA0DGaLdtR17VQP4DxC0Ao/getUpdates
telegram.vendor.ptb_urllib3.urllib3.connectionpool - WARNING - Retrying (Retry(total=0, connect=None, read=None, redirect=None)) after connection broken by 'NewConnectionError('<telegram.vendor.ptb_urllib3.urllib3.contrib.socks.SOCKSHTTPSConnection object at 0x0000000004D0ACA0>: Failed to establish a new connection: [Errno 11004] getaddrinfo failed')': /bot1998874930:AAHSRnVPn6qTkHA0DGaLdtR17VQP4DxC0Ao/getUpdates
telegram.ext.updater - ERROR - Error while getting Updates: urllib3 HTTPError SOCKSHTTPSConnectionPool(host='api.telegram.org', port=443): Max retries exceeded with url: /bot1998874930:AAHSRnVPn6qTkHA0DGaLdtR17VQP4DxC0Ao/getUpdates (Caused by NewConnectionError('<telegram.vendor.ptb_urllib3.urllib3.contrib.socks.SOCKSHTTPSConnection object at 0x0000000004D0ADF0>: Failed to establish a new connection: [Errno 11004] getaddrinfo failed'))
telegram.ext.dispatcher - ERROR - No error handlers are registered, logging exception.
Traceback (most recent call last):
  File "C:\Users\питер\AppData\Local\Programs\Python\Python38\lib\site-packages\telegram\vendor\ptb_urllib3\urllib3\contrib\socks.py", line 79, in _new_conn
    conn = socks.create_connection(
  File "C:\Users\питер\AppData\Local\Programs\Python\Python38\lib\site-packages\socks.py", line 180, in create_connection
    for r in socket.getaddrinfo(proxy_addr, proxy_port, 0, socket.SOCK_STREAM):
  File "C:\Users\питер\AppData\Local\Programs\Python\Python38\lib\socket.py", line 918, in getaddrinfo
    for res in _socket.getaddrinfo(host, port, family, type, proto, flags):
socket.gaierror: [Errno 11004] getaddrinfo failed

During handling of the above exception, another exception occurred:

Traceback (most recent call last):
  File "C:\Users\питер\AppData\Local\Programs\Python\Python38\lib\site-packages\telegram\vendor\ptb_urllib3\urllib3\connectionpool.py", line 614, in urlopen
    httplib_response = self._make_request(conn, method, url,
  File "C:\Users\питер\AppData\Local\Programs\Python\Python38\lib\site-packages\telegram\vendor\ptb_urllib3\urllib3\connectionpool.py", line 360, in _make_request
    self._validate_conn(conn)
  File "C:\Users\питер\AppData\Local\Programs\Python\Python38\lib\site-packages\telegram\vendor\ptb_urllib3\urllib3\connectionpool.py", line 857, in _validate_conn
    super(HTTPSConnectionPool, self)._validate_conn(conn)
  File "C:\Users\питер\AppData\Local\Programs\Python\Python38\lib\site-packages\telegram\vendor\ptb_urllib3\urllib3\connectionpool.py", line 289, in _validate_conn
    conn.connect()
  File "C:\Users\питер\AppData\Local\Programs\Python\Python38\lib\site-packages\telegram\vendor\ptb_urllib3\urllib3\connection.py", line 284, in connect
    conn = self._new_conn()
  File "C:\Users\питер\AppData\Local\Programs\Python\Python38\lib\site-packages\telegram\vendor\ptb_urllib3\urllib3\contrib\socks.py", line 119, in _new_conn
    raise NewConnectionError(
telegram.vendor.ptb_urllib3.urllib3.exceptions.NewConnectionError: <telegram.vendor.ptb_urllib3.urllib3.contrib.socks.SOCKSHTTPSConnection object at 0x0000000004D0ADF0>: Failed to establish a new connection: [Errno 11004] getaddrinfo failed

During handling of the above exception, another exception occurred:

Traceback (most recent call last):
  File "C:\Users\питер\AppData\Local\Programs\Python\Python38\lib\site-packages\telegram\utils\request.py", line 259, in _request_wrapper
    resp = self._con_pool.request(*args, **kwargs)
  File "C:\Users\питер\AppData\Local\Programs\Python\Python38\lib\site-packages\telegram\vendor\ptb_urllib3\urllib3\request.py", line 68, in request
    return self.request_encode_body(method, url, fields=fields,
  File "C:\Users\питер\AppData\Local\Programs\Python\Python38\lib\site-packages\telegram\vendor\ptb_urllib3\urllib3\request.py", line 148, in request_encode_body
    return self.urlopen(method, url, **extra_kw)
  File "C:\Users\питер\AppData\Local\Programs\Python\Python38\lib\site-packages\telegram\vendor\ptb_urllib3\urllib3\poolmanager.py", line 244, in urlopen
    response = conn.urlopen(method, u.request_uri, **kw)
  File "C:\Users\питер\AppData\Local\Programs\Python\Python38\lib\site-packages\telegram\vendor\ptb_urllib3\urllib3\connectionpool.py", line 691, in urlopen
    return self.urlopen(method, url, body, headers, retries,
  File "C:\Users\питер\AppData\Local\Programs\Python\Python38\lib\site-packages\telegram\vendor\ptb_urllib3\urllib3\connectionpool.py", line 691, in urlopen
    return self.urlopen(method, url, body, headers, retries,
  File "C:\Users\питер\AppData\Local\Programs\Python\Python38\lib\site-packages\telegram\vendor\ptb_urllib3\urllib3\connectionpool.py", line 691, in urlopen
    return self.urlopen(method, url, body, headers, retries,
  File "C:\Users\питер\AppData\Local\Programs\Python\Python38\lib\site-packages\telegram\vendor\ptb_urllib3\urllib3\connectionpool.py", line 665, in urlopen
    retries = retries.increment(method, url, error=e, _pool=self,
  File "C:\Users\питер\AppData\Local\Programs\Python\Python38\lib\site-packages\telegram\vendor\ptb_urllib3\urllib3\util\retry.py", line 376, in increment
    raise MaxRetryError(_pool, url, error or ResponseError(cause))
telegram.vendor.ptb_urllib3.urllib3.exceptions.MaxRetryError: SOCKSHTTPSConnectionPool(host='api.telegram.org', port=443): Max retries exceeded with url: /bot1998874930:AAHSRnVPn6qTkHA0DGaLdtR17VQP4DxC0Ao/getUpdates (Caused by NewConnectionError('<telegram.vendor.ptb_urllib3.urllib3.contrib.socks.SOCKSHTTPSConnection object at 0x0000000004D0ADF0>: Failed to establish a new connection: [Errno 11004] getaddrinfo failed'))

The above exception was the direct cause of the following exception:

Traceback (most recent call last):
  File "C:\Users\питер\AppData\Local\Programs\Python\Python38\lib\site-packages\telegram\ext\updater.py", line 646, in _network_loop_retry
    if not action_cb():
  File "C:\Users\питер\AppData\Local\Programs\Python\Python38\lib\site-packages\telegram\ext\updater.py", line 597, in polling_action_cb
    updates = self.bot.get_updates(
  File "C:\Users\питер\AppData\Local\Programs\Python\Python38\lib\site-packages\telegram\ext\extbot.py", line 222, in get_updates
    updates = super().get_updates(
  File "C:\Users\питер\AppData\Local\Programs\Python\Python38\lib\site-packages\telegram\bot.py", line 130, in decorator
    result = func(*args, **kwargs)
  File "C:\Users\питер\AppData\Local\Programs\Python\Python38\lib\site-packages\telegram\bot.py", line 2861, in get_updates
    self._post(
  File "C:\Users\питер\AppData\Local\Programs\Python\Python38\lib\site-packages\telegram\bot.py", line 295, in _post
    return self.request.post(
  File "C:\Users\питер\AppData\Local\Programs\Python\Python38\lib\site-packages\telegram\utils\request.py", line 356, in post
    result = self._request_wrapper(
  File "C:\Users\питер\AppData\Local\Programs\Python\Python38\lib\site-packages\telegram\utils\request.py", line 265, in _request_wrapper
    raise NetworkError(f'urllib3 HTTPError {error}') from error
telegram.error.NetworkError: urllib3 HTTPError SOCKSHTTPSConnectionPool(host='api.telegram.org', port=443): Max retries exceeded with url: /bot1998874930:AAHSRnVPn6qTkHA0DGaLdtR17VQP4DxC0Ao/getUpdates (Caused by NewConnectionError('<telegram.vendor.ptb_urllib3.urllib3.contrib.socks.SOCKSHTTPSConnection object at 0x0000000004D0ADF0>: Failed to establish a new connection: [Errno 11004] getaddrinfo failed'))
telegram.vendor.ptb_urllib3.urllib3.connectionpool - WARNING - Retrying (Retry(total=2, connect=None, read=None, redirect=None)) after connection broken by 'NewConnectionError('<telegram.vendor.ptb_urllib3.urllib3.contrib.socks.SOCKSHTTPSConnection object at 0x00000000049EAFA0>: Failed to establish a new connection: [Errno 11004] getaddrinfo failed')': /bot1998874930:AAHSRnVPn6qTkHA0DGaLdtR17VQP4DxC0Ao/getUpdates
telegram.vendor.ptb_urllib3.urllib3.connectionpool - WARNING - Retrying (Retry(total=1, connect=None, read=None, redirect=None)) after connection broken by 'NewConnectionError('<telegram.vendor.ptb_urllib3.urllib3.contrib.socks.SOCKSHTTPSConnection object at 0x00000000049EAE80>: Failed to establish a new connection: [Errno 11004] getaddrinfo failed')': /bot1998874930:AAHSRnVPn6qTkHA0DGaLdtR17VQP4DxC0Ao/getUpdates
telegram.vendor.ptb_urllib3.urllib3.connectionpool - WARNING - Retrying (Retry(total=0, connect=None, read=None, redirect=None)) after connection broken by 'NewConnectionError('<telegram.vendor.ptb_urllib3.urllib3.contrib.socks.SOCKSHTTPSConnection object at 0x00000000049EA2B0>: Failed to establish a new connection: [Errno 11004] getaddrinfo failed')': /bot1998874930:AAHSRnVPn6qTkHA0DGaLdtR17VQP4DxC0Ao/getUpdates
telegram.ext.updater - ERROR - Error while getting Updates: urllib3 HTTPError SOCKSHTTPSConnectionPool(host='api.telegram.org', port=443): Max retries exceeded with url: /bot1998874930:AAHSRnVPn6qTkHA0DGaLdtR17VQP4DxC0Ao/getUpdates (Caused by NewConnectionError('<telegram.vendor.ptb_urllib3.urllib3.contrib.socks.SOCKSHTTPSConnection object at 0x00000000049EA3A0>: Failed to establish a new connection: [Errno 11004] getaddrinfo failed'))
telegram.ext.dispatcher - ERROR - No error handlers are registered, logging exception.
Traceback (most recent call last):
  File "C:\Users\питер\AppData\Local\Programs\Python\Python38\lib\site-packages\telegram\vendor\ptb_urllib3\urllib3\contrib\socks.py", line 79, in _new_conn
    conn = socks.create_connection(
  File "C:\Users\питер\AppData\Local\Programs\Python\Python38\lib\site-packages\socks.py", line 180, in create_connection
    for r in socket.getaddrinfo(proxy_addr, proxy_port, 0, socket.SOCK_STREAM):
  File "C:\Users\питер\AppData\Local\Programs\Python\Python38\lib\socket.py", line 918, in getaddrinfo
    for res in _socket.getaddrinfo(host, port, family, type, proto, flags):
socket.gaierror: [Errno 11004] getaddrinfo failed

During handling of the above exception, another exception occurred:

Traceback (most recent call last):
  File "C:\Users\питер\AppData\Local\Programs\Python\Python38\lib\site-packages\telegram\vendor\ptb_urllib3\urllib3\connectionpool.py", line 614, in urlopen
    httplib_response = self._make_request(conn, method, url,
  File "C:\Users\питер\AppData\Local\Programs\Python\Python38\lib\site-packages\telegram\vendor\ptb_urllib3\urllib3\connectionpool.py", line 360, in _make_request
    self._validate_conn(conn)
  File "C:\Users\питер\AppData\Local\Programs\Python\Python38\lib\site-packages\telegram\vendor\ptb_urllib3\urllib3\connectionpool.py", line 857, in _validate_conn
    super(HTTPSConnectionPool, self)._validate_conn(conn)
  File "C:\Users\питер\AppData\Local\Programs\Python\Python38\lib\site-packages\telegram\vendor\ptb_urllib3\urllib3\connectionpool.py", line 289, in _validate_conn
    conn.connect()
  File "C:\Users\питер\AppData\Local\Programs\Python\Python38\lib\site-packages\telegram\vendor\ptb_urllib3\urllib3\connection.py", line 284, in connect
    conn = self._new_conn()
  File "C:\Users\питер\AppData\Local\Programs\Python\Python38\lib\site-packages\telegram\vendor\ptb_urllib3\urllib3\contrib\socks.py", line 119, in _new_conn
    raise NewConnectionError(
telegram.vendor.ptb_urllib3.urllib3.exceptions.NewConnectionError: <telegram.vendor.ptb_urllib3.urllib3.contrib.socks.SOCKSHTTPSConnection object at 0x00000000049EA3A0>: Failed to establish a new connection: [Errno 11004] getaddrinfo failed

During handling of the above exception, another exception occurred:

Traceback (most recent call last):
  File "C:\Users\питер\AppData\Local\Programs\Python\Python38\lib\site-packages\telegram\utils\request.py", line 259, in _request_wrapper
    resp = self._con_pool.request(*args, **kwargs)
  File "C:\Users\питер\AppData\Local\Programs\Python\Python38\lib\site-packages\telegram\vendor\ptb_urllib3\urllib3\request.py", line 68, in request
    return self.request_encode_body(method, url, fields=fields,
  File "C:\Users\питер\AppData\Local\Programs\Python\Python38\lib\site-packages\telegram\vendor\ptb_urllib3\urllib3\request.py", line 148, in request_encode_body
    return self.urlopen(method, url, **extra_kw)
  File "C:\Users\питер\AppData\Local\Programs\Python\Python38\lib\site-packages\telegram\vendor\ptb_urllib3\urllib3\poolmanager.py", line 244, in urlopen
    response = conn.urlopen(method, u.request_uri, **kw)
  File "C:\Users\питер\AppData\Local\Programs\Python\Python38\lib\site-packages\telegram\vendor\ptb_urllib3\urllib3\connectionpool.py", line 691, in urlopen
    return self.urlopen(method, url, body, headers, retries,
  File "C:\Users\питер\AppData\Local\Programs\Python\Python38\lib\site-packages\telegram\vendor\ptb_urllib3\urllib3\connectionpool.py", line 691, in urlopen
    return self.urlopen(method, url, body, headers, retries,
  File "C:\Users\питер\AppData\Local\Programs\Python\Python38\lib\site-packages\telegram\vendor\ptb_urllib3\urllib3\connectionpool.py", line 691, in urlopen
    return self.urlopen(method, url, body, headers, retries,
  File "C:\Users\питер\AppData\Local\Programs\Python\Python38\lib\site-packages\telegram\vendor\ptb_urllib3\urllib3\connectionpool.py", line 665, in urlopen
    retries = retries.increment(method, url, error=e, _pool=self,
  File "C:\Users\питер\AppData\Local\Programs\Python\Python38\lib\site-packages\telegram\vendor\ptb_urllib3\urllib3\util\retry.py", line 376, in increment
    raise MaxRetryError(_pool, url, error or ResponseError(cause))
telegram.vendor.ptb_urllib3.urllib3.exceptions.MaxRetryError: SOCKSHTTPSConnectionPool(host='api.telegram.org', port=443): Max retries exceeded with url: /bot1998874930:AAHSRnVPn6qTkHA0DGaLdtR17VQP4DxC0Ao/getUpdates (Caused by NewConnectionError('<telegram.vendor.ptb_urllib3.urllib3.contrib.socks.SOCKSHTTPSConnection object at 0x00000000049EA3A0>: Failed to establish a new connection: [Errno 11004] getaddrinfo failed'))

The above exception was the direct cause of the following exception:

Traceback (most recent call last):
  File "C:\Users\питер\AppData\Local\Programs\Python\Python38\lib\site-packages\telegram\ext\updater.py", line 646, in _network_loop_retry
    if not action_cb():
  File "C:\Users\питер\AppData\Local\Programs\Python\Python38\lib\site-packages\telegram\ext\updater.py", line 597, in polling_action_cb
    updates = self.bot.get_updates(
  File "C:\Users\питер\AppData\Local\Programs\Python\Python38\lib\site-packages\telegram\ext\extbot.py", line 222, in get_updates
    updates = super().get_updates(
  File "C:\Users\питер\AppData\Local\Programs\Python\Python38\lib\site-packages\telegram\bot.py", line 130, in decorator
    result = func(*args, **kwargs)
  File "C:\Users\питер\AppData\Local\Programs\Python\Python38\lib\site-packages\telegram\bot.py", line 2861, in get_updates
    self._post(
  File "C:\Users\питер\AppData\Local\Programs\Python\Python38\lib\site-packages\telegram\bot.py", line 295, in _post
    return self.request.post(
  File "C:\Users\питер\AppData\Local\Programs\Python\Python38\lib\site-packages\telegram\utils\request.py", line 356, in post
    result = self._request_wrapper(
  File "C:\Users\питер\AppData\Local\Programs\Python\Python38\lib\site-packages\telegram\utils\request.py", line 265, in _request_wrapper
    raise NetworkError(f'urllib3 HTTPError {error}') from error
telegram.error.NetworkError: urllib3 HTTPError SOCKSHTTPSConnectionPool(host='api.telegram.org', port=443): Max retries exceeded with url: /bot1998874930:AAHSRnVPn6qTkHA0DGaLdtR17VQP4DxC0Ao/getUpdates (Caused by NewConnectionError('<telegram.vendor.ptb_urllib3.urllib3.contrib.socks.SOCKSHTTPSConnection object at 0x00000000049EA3A0>: Failed to establish a new connection: [Errno 11004] getaddrinfo failed'))
telegram.vendor.ptb_urllib3.urllib3.connectionpool - WARNING - Retrying (Retry(total=2, connect=None, read=None, redirect=None)) after connection broken by 'NewConnectionError('<telegram.vendor.ptb_urllib3.urllib3.contrib.socks.SOCKSHTTPSConnection object at 0x00000000049E2850>: Failed to establish a new connection: [Errno 11004] getaddrinfo failed')': /bot1998874930:AAHSRnVPn6qTkHA0DGaLdtR17VQP4DxC0Ao/getUpdates
telegram.vendor.ptb_urllib3.urllib3.connectionpool - WARNING - Retrying (Retry(total=1, connect=None, read=None, redirect=None)) after connection broken by 'NewConnectionError('<telegram.vendor.ptb_urllib3.urllib3.contrib.socks.SOCKSHTTPSConnection object at 0x0000000004D0AE50>: Failed to establish a new connection: [Errno 11004] getaddrinfo failed')': /bot1998874930:AAHSRnVPn6qTkHA0DGaLdtR17VQP4DxC0Ao/getUpdates
telegram.vendor.ptb_urllib3.urllib3.connectionpool - WARNING - Retrying (Retry(total=0, connect=None, read=None, redirect=None)) after connection broken by 'NewConnectionError('<telegram.vendor.ptb_urllib3.urllib3.contrib.socks.SOCKSHTTPSConnection object at 0x0000000004D0A9A0>: Failed to establish a new connection: [Errno 11004] getaddrinfo failed')': /bot1998874930:AAHSRnVPn6qTkHA0DGaLdtR17VQP4DxC0Ao/getUpdates
telegram.ext.updater - ERROR - Error while getting Updates: urllib3 HTTPError SOCKSHTTPSConnectionPool(host='api.telegram.org', port=443): Max retries exceeded with url: /bot1998874930:AAHSRnVPn6qTkHA0DGaLdtR17VQP4DxC0Ao/getUpdates (Caused by NewConnectionError('<telegram.vendor.ptb_urllib3.urllib3.contrib.socks.SOCKSHTTPSConnection object at 0x0000000004D0A5B0>: Failed to establish a new connection: [Errno 11004] getaddrinfo failed'))
telegram.ext.dispatcher - ERROR - No error handlers are registered, logging exception.
Traceback (most recent call last):
  File "C:\Users\питер\AppData\Local\Programs\Python\Python38\lib\site-packages\telegram\vendor\ptb_urllib3\urllib3\contrib\socks.py", line 79, in _new_conn
    conn = socks.create_connection(
  File "C:\Users\питер\AppData\Local\Programs\Python\Python38\lib\site-packages\socks.py", line 180, in create_connection
    for r in socket.getaddrinfo(proxy_addr, proxy_port, 0, socket.SOCK_STREAM):
  File "C:\Users\питер\AppData\Local\Programs\Python\Python38\lib\socket.py", line 918, in getaddrinfo
    for res in _socket.getaddrinfo(host, port, family, type, proto, flags):
socket.gaierror: [Errno 11004] getaddrinfo failed

During handling of the above exception, another exception occurred:

Traceback (most recent call last):
  File "C:\Users\питер\AppData\Local\Programs\Python\Python38\lib\site-packages\telegram\vendor\ptb_urllib3\urllib3\connectionpool.py", line 614, in urlopen
    httplib_response = self._make_request(conn, method, url,
  File "C:\Users\питер\AppData\Local\Programs\Python\Python38\lib\site-packages\telegram\vendor\ptb_urllib3\urllib3\connectionpool.py", line 360, in _make_request
    self._validate_conn(conn)
  File "C:\Users\питер\AppData\Local\Programs\Python\Python38\lib\site-packages\telegram\vendor\ptb_urllib3\urllib3\connectionpool.py", line 857, in _validate_conn
    super(HTTPSConnectionPool, self)._validate_conn(conn)
  File "C:\Users\питер\AppData\Local\Programs\Python\Python38\lib\site-packages\telegram\vendor\ptb_urllib3\urllib3\connectionpool.py", line 289, in _validate_conn
    conn.connect()
  File "C:\Users\питер\AppData\Local\Programs\Python\Python38\lib\site-packages\telegram\vendor\ptb_urllib3\urllib3\connection.py", line 284, in connect
    conn = self._new_conn()
  File "C:\Users\питер\AppData\Local\Programs\Python\Python38\lib\site-packages\telegram\vendor\ptb_urllib3\urllib3\contrib\socks.py", line 119, in _new_conn
    raise NewConnectionError(
telegram.vendor.ptb_urllib3.urllib3.exceptions.NewConnectionError: <telegram.vendor.ptb_urllib3.urllib3.contrib.socks.SOCKSHTTPSConnection object at 0x0000000004D0A5B0>: Failed to establish a new connection: [Errno 11004] getaddrinfo failed

During handling of the above exception, another exception occurred:

Traceback (most recent call last):
  File "C:\Users\питер\AppData\Local\Programs\Python\Python38\lib\site-packages\telegram\utils\request.py", line 259, in _request_wrapper
    resp = self._con_pool.request(*args, **kwargs)
  File "C:\Users\питер\AppData\Local\Programs\Python\Python38\lib\site-packages\telegram\vendor\ptb_urllib3\urllib3\request.py", line 68, in request
    return self.request_encode_body(method, url, fields=fields,
  File "C:\Users\питер\AppData\Local\Programs\Python\Python38\lib\site-packages\telegram\vendor\ptb_urllib3\urllib3\request.py", line 148, in request_encode_body
    return self.urlopen(method, url, **extra_kw)
  File "C:\Users\питер\AppData\Local\Programs\Python\Python38\lib\site-packages\telegram\vendor\ptb_urllib3\urllib3\poolmanager.py", line 244, in urlopen
    response = conn.urlopen(method, u.request_uri, **kw)
  File "C:\Users\питер\AppData\Local\Programs\Python\Python38\lib\site-packages\telegram\vendor\ptb_urllib3\urllib3\connectionpool.py", line 691, in urlopen
    return self.urlopen(method, url, body, headers, retries,
  File "C:\Users\питер\AppData\Local\Programs\Python\Python38\lib\site-packages\telegram\vendor\ptb_urllib3\urllib3\connectionpool.py", line 691, in urlopen
    return self.urlopen(method, url, body, headers, retries,
  File "C:\Users\питер\AppData\Local\Programs\Python\Python38\lib\site-packages\telegram\vendor\ptb_urllib3\urllib3\connectionpool.py", line 691, in urlopen
    return self.urlopen(method, url, body, headers, retries,
  File "C:\Users\питер\AppData\Local\Programs\Python\Python38\lib\site-packages\telegram\vendor\ptb_urllib3\urllib3\connectionpool.py", line 665, in urlopen
    retries = retries.increment(method, url, error=e, _pool=self,
  File "C:\Users\питер\AppData\Local\Programs\Python\Python38\lib\site-packages\telegram\vendor\ptb_urllib3\urllib3\util\retry.py", line 376, in increment
    raise MaxRetryError(_pool, url, error or ResponseError(cause))
telegram.vendor.ptb_urllib3.urllib3.exceptions.MaxRetryError: SOCKSHTTPSConnectionPool(host='api.telegram.org', port=443): Max retries exceeded with url: /bot1998874930:AAHSRnVPn6qTkHA0DGaLdtR17VQP4DxC0Ao/getUpdates (Caused by NewConnectionError('<telegram.vendor.ptb_urllib3.urllib3.contrib.socks.SOCKSHTTPSConnection object at 0x0000000004D0A5B0>: Failed to establish a new connection: [Errno 11004] getaddrinfo failed'))

The above exception was the direct cause of the following exception:

Traceback (most recent call last):
  File "C:\Users\питер\AppData\Local\Programs\Python\Python38\lib\site-packages\telegram\ext\updater.py", line 646, in _network_loop_retry
    if not action_cb():
  File "C:\Users\питер\AppData\Local\Programs\Python\Python38\lib\site-packages\telegram\ext\updater.py", line 597, in polling_action_cb
    updates = self.bot.get_updates(
  File "C:\Users\питер\AppData\Local\Programs\Python\Python38\lib\site-packages\telegram\ext\extbot.py", line 222, in get_updates
    updates = super().get_updates(
  File "C:\Users\питер\AppData\Local\Programs\Python\Python38\lib\site-packages\telegram\bot.py", line 130, in decorator
    result = func(*args, **kwargs)
  File "C:\Users\питер\AppData\Local\Programs\Python\Python38\lib\site-packages\telegram\bot.py", line 2861, in get_updates
    self._post(
  File "C:\Users\питер\AppData\Local\Programs\Python\Python38\lib\site-packages\telegram\bot.py", line 295, in _post
    return self.request.post(
  File "C:\Users\питер\AppData\Local\Programs\Python\Python38\lib\site-packages\telegram\utils\request.py", line 356, in post
    result = self._request_wrapper(
  File "C:\Users\питер\AppData\Local\Programs\Python\Python38\lib\site-packages\telegram\utils\request.py", line 265, in _request_wrapper
    raise NetworkError(f'urllib3 HTTPError {error}') from error
telegram.error.NetworkError: urllib3 HTTPError SOCKSHTTPSConnectionPool(host='api.telegram.org', port=443): Max retries exceeded with url: /bot1998874930:AAHSRnVPn6qTkHA0DGaLdtR17VQP4DxC0Ao/getUpdates (Caused by NewConnectionError('<telegram.vendor.ptb_urllib3.urllib3.contrib.socks.SOCKSHTTPSConnection object at 0x0000000004D0A5B0>: Failed to establish a new connection: [Errno 11004] getaddrinfo failed'))
telegram.vendor.ptb_urllib3.urllib3.connectionpool - WARNING - Retrying (Retry(total=2, connect=None, read=None, redirect=None)) after connection broken by 'NewConnectionError('<telegram.vendor.ptb_urllib3.urllib3.contrib.socks.SOCKSHTTPSConnection object at 0x00000000049EAC10>: Failed to establish a new connection: [Errno 11004] getaddrinfo failed')': /bot1998874930:AAHSRnVPn6qTkHA0DGaLdtR17VQP4DxC0Ao/getUpdates
telegram.vendor.ptb_urllib3.urllib3.connectionpool - WARNING - Retrying (Retry(total=1, connect=None, read=None, redirect=None)) after connection broken by 'NewConnectionError('<telegram.vendor.ptb_urllib3.urllib3.contrib.socks.SOCKSHTTPSConnection object at 0x0000000004D0A460>: Failed to establish a new connection: [Errno 11004] getaddrinfo failed')': /bot1998874930:AAHSRnVPn6qTkHA0DGaLdtR17VQP4DxC0Ao/getUpdates
telegram.vendor.ptb_urllib3.urllib3.connectionpool - WARNING - Retrying (Retry(total=0, connect=None, read=None, redirect=None)) after connection broken by 'NewConnectionError('<telegram.vendor.ptb_urllib3.urllib3.contrib.socks.SOCKSHTTPSConnection object at 0x0000000004D0A040>: Failed to establish a new connection: [Errno 11004] getaddrinfo failed')': /bot1998874930:AAHSRnVPn6qTkHA0DGaLdtR17VQP4DxC0Ao/getUpdates
telegram.ext.updater - ERROR - Error while getting Updates: urllib3 HTTPError SOCKSHTTPSConnectionPool(host='api.telegram.org', port=443): Max retries exceeded with url: /bot1998874930:AAHSRnVPn6qTkHA0DGaLdtR17VQP4DxC0Ao/getUpdates (Caused by NewConnectionError('<telegram.vendor.ptb_urllib3.urllib3.contrib.socks.SOCKSHTTPSConnection object at 0x0000000004D0AFA0>: Failed to establish a new connection: [Errno 11004] getaddrinfo failed'))
telegram.ext.dispatcher - ERROR - No error handlers are registered, logging exception.
Traceback (most recent call last):
  File "C:\Users\питер\AppData\Local\Programs\Python\Python38\lib\site-packages\telegram\vendor\ptb_urllib3\urllib3\contrib\socks.py", line 79, in _new_conn
    conn = socks.create_connection(
  File "C:\Users\питер\AppData\Local\Programs\Python\Python38\lib\site-packages\socks.py", line 180, in create_connection
    for r in socket.getaddrinfo(proxy_addr, proxy_port, 0, socket.SOCK_STREAM):
  File "C:\Users\питер\AppData\Local\Programs\Python\Python38\lib\socket.py", line 918, in getaddrinfo
    for res in _socket.getaddrinfo(host, port, family, type, proto, flags):
socket.gaierror: [Errno 11004] getaddrinfo failed

During handling of the above exception, another exception occurred:

Traceback (most recent call last):
  File "C:\Users\питер\AppData\Local\Programs\Python\Python38\lib\site-packages\telegram\vendor\ptb_urllib3\urllib3\connectionpool.py", line 614, in urlopen
    httplib_response = self._make_request(conn, method, url,
  File "C:\Users\питер\AppData\Local\Programs\Python\Python38\lib\site-packages\telegram\vendor\ptb_urllib3\urllib3\connectionpool.py", line 360, in _make_request
    self._validate_conn(conn)
  File "C:\Users\питер\AppData\Local\Programs\Python\Python38\lib\site-packages\telegram\vendor\ptb_urllib3\urllib3\connectionpool.py", line 857, in _validate_conn
    super(HTTPSConnectionPool, self)._validate_conn(conn)
  File "C:\Users\питер\AppData\Local\Programs\Python\Python38\lib\site-packages\telegram\vendor\ptb_urllib3\urllib3\connectionpool.py", line 289, in _validate_conn
    conn.connect()
  File "C:\Users\питер\AppData\Local\Programs\Python\Python38\lib\site-packages\telegram\vendor\ptb_urllib3\urllib3\connection.py", line 284, in connect
    conn = self._new_conn()
  File "C:\Users\питер\AppData\Local\Programs\Python\Python38\lib\site-packages\telegram\vendor\ptb_urllib3\urllib3\contrib\socks.py", line 119, in _new_conn
    raise NewConnectionError(
telegram.vendor.ptb_urllib3.urllib3.exceptions.NewConnectionError: <telegram.vendor.ptb_urllib3.urllib3.contrib.socks.SOCKSHTTPSConnection object at 0x0000000004D0AFA0>: Failed to establish a new connection: [Errno 11004] getaddrinfo failed

During handling of the above exception, another exception occurred:

Traceback (most recent call last):
  File "C:\Users\питер\AppData\Local\Programs\Python\Python38\lib\site-packages\telegram\utils\request.py", line 259, in _request_wrapper
    resp = self._con_pool.request(*args, **kwargs)
  File "C:\Users\питер\AppData\Local\Programs\Python\Python38\lib\site-packages\telegram\vendor\ptb_urllib3\urllib3\request.py", line 68, in request
    return self.request_encode_body(method, url, fields=fields,
  File "C:\Users\питер\AppData\Local\Programs\Python\Python38\lib\site-packages\telegram\vendor\ptb_urllib3\urllib3\request.py", line 148, in request_encode_body
    return self.urlopen(method, url, **extra_kw)
  File "C:\Users\питер\AppData\Local\Programs\Python\Python38\lib\site-packages\telegram\vendor\ptb_urllib3\urllib3\poolmanager.py", line 244, in urlopen
    response = conn.urlopen(method, u.request_uri, **kw)
  File "C:\Users\питер\AppData\Local\Programs\Python\Python38\lib\site-packages\telegram\vendor\ptb_urllib3\urllib3\connectionpool.py", line 691, in urlopen
    return self.urlopen(method, url, body, headers, retries,
  File "C:\Users\питер\AppData\Local\Programs\Python\Python38\lib\site-packages\telegram\vendor\ptb_urllib3\urllib3\connectionpool.py", line 691, in urlopen
    return self.urlopen(method, url, body, headers, retries,
  File "C:\Users\питер\AppData\Local\Programs\Python\Python38\lib\site-packages\telegram\vendor\ptb_urllib3\urllib3\connectionpool.py", line 691, in urlopen
    return self.urlopen(method, url, body, headers, retries,
  File "C:\Users\питер\AppData\Local\Programs\Python\Python38\lib\site-packages\telegram\vendor\ptb_urllib3\urllib3\connectionpool.py", line 665, in urlopen
    retries = retries.increment(method, url, error=e, _pool=self,
  File "C:\Users\питер\AppData\Local\Programs\Python\Python38\lib\site-packages\telegram\vendor\ptb_urllib3\urllib3\util\retry.py", line 376, in increment
    raise MaxRetryError(_pool, url, error or ResponseError(cause))
telegram.vendor.ptb_urllib3.urllib3.exceptions.MaxRetryError: SOCKSHTTPSConnectionPool(host='api.telegram.org', port=443): Max retries exceeded with url: /bot1998874930:AAHSRnVPn6qTkHA0DGaLdtR17VQP4DxC0Ao/getUpdates (Caused by NewConnectionError('<telegram.vendor.ptb_urllib3.urllib3.contrib.socks.SOCKSHTTPSConnection object at 0x0000000004D0AFA0>: Failed to establish a new connection: [Errno 11004] getaddrinfo failed'))

The above exception was the direct cause of the following exception:

Traceback (most recent call last):
  File "C:\Users\питер\AppData\Local\Programs\Python\Python38\lib\site-packages\telegram\ext\updater.py", line 646, in _network_loop_retry
    if not action_cb():
  File "C:\Users\питер\AppData\Local\Programs\Python\Python38\lib\site-packages\telegram\ext\updater.py", line 597, in polling_action_cb
    updates = self.bot.get_updates(
  File "C:\Users\питер\AppData\Local\Programs\Python\Python38\lib\site-packages\telegram\ext\extbot.py", line 222, in get_updates
    updates = super().get_updates(
  File "C:\Users\питер\AppData\Local\Programs\Python\Python38\lib\site-packages\telegram\bot.py", line 130, in decorator
    result = func(*args, **kwargs)
  File "C:\Users\питер\AppData\Local\Programs\Python\Python38\lib\site-packages\telegram\bot.py", line 2861, in get_updates
    self._post(
  File "C:\Users\питер\AppData\Local\Programs\Python\Python38\lib\site-packages\telegram\bot.py", line 295, in _post
    return self.request.post(
  File "C:\Users\питер\AppData\Local\Programs\Python\Python38\lib\site-packages\telegram\utils\request.py", line 356, in post
    result = self._request_wrapper(
  File "C:\Users\питер\AppData\Local\Programs\Python\Python38\lib\site-packages\telegram\utils\request.py", line 265, in _request_wrapper
    raise NetworkError(f'urllib3 HTTPError {error}') from error
telegram.error.NetworkError: urllib3 HTTPError SOCKSHTTPSConnectionPool(host='api.telegram.org', port=443): Max retries exceeded with url: /bot1998874930:AAHSRnVPn6qTkHA0DGaLdtR17VQP4DxC0Ao/getUpdates (Caused by NewConnectionError('<telegram.vendor.ptb_urllib3.urllib3.contrib.socks.SOCKSHTTPSConnection object at 0x0000000004D0AFA0>: Failed to establish a new connection: [Errno 11004] getaddrinfo failed'))
telegram.vendor.ptb_urllib3.urllib3.connectionpool - WARNING - Retrying (Retry(total=2, connect=None, read=None, redirect=None)) after connection broken by 'NewConnectionError('<telegram.vendor.ptb_urllib3.urllib3.contrib.socks.SOCKSHTTPSConnection object at 0x00000000049EA7F0>: Failed to establish a new connection: [Errno 11004] getaddrinfo failed')': /bot1998874930:AAHSRnVPn6qTkHA0DGaLdtR17VQP4DxC0Ao/getUpdates
telegram.vendor.ptb_urllib3.urllib3.connectionpool - WARNING - Retrying (Retry(total=1, connect=None, read=None, redirect=None)) after connection broken by 'NewConnectionError('<telegram.vendor.ptb_urllib3.urllib3.contrib.socks.SOCKSHTTPSConnection object at 0x0000000004D1C190>: Failed to establish a new connection: [Errno 11004] getaddrinfo failed')': /bot1998874930:AAHSRnVPn6qTkHA0DGaLdtR17VQP4DxC0Ao/getUpdates
telegram.vendor.ptb_urllib3.urllib3.connectionpool - WARNING - Retrying (Retry(total=0, connect=None, read=None, redirect=None)) after connection broken by 'NewConnectionError('<telegram.vendor.ptb_urllib3.urllib3.contrib.socks.SOCKSHTTPSConnection object at 0x0000000004D1C2E0>: Failed to establish a new connection: [Errno 11004] getaddrinfo failed')': /bot1998874930:AAHSRnVPn6qTkHA0DGaLdtR17VQP4DxC0Ao/getUpdates
telegram.ext.updater - ERROR - Error while getting Updates: urllib3 HTTPError SOCKSHTTPSConnectionPool(host='api.telegram.org', port=443): Max retries exceeded with url: /bot1998874930:AAHSRnVPn6qTkHA0DGaLdtR17VQP4DxC0Ao/getUpdates (Caused by NewConnectionError('<telegram.vendor.ptb_urllib3.urllib3.contrib.socks.SOCKSHTTPSConnection object at 0x0000000004D1C430>: Failed to establish a new connection: [Errno 11004] getaddrinfo failed'))
telegram.ext.dispatcher - ERROR - No error handlers are registered, logging exception.
Traceback (most recent call last):
  File "C:\Users\питер\AppData\Local\Programs\Python\Python38\lib\site-packages\telegram\vendor\ptb_urllib3\urllib3\contrib\socks.py", line 79, in _new_conn
    conn = socks.create_connection(
  File "C:\Users\питер\AppData\Local\Programs\Python\Python38\lib\site-packages\socks.py", line 180, in create_connection
    for r in socket.getaddrinfo(proxy_addr, proxy_port, 0, socket.SOCK_STREAM):
  File "C:\Users\питер\AppData\Local\Programs\Python\Python38\lib\socket.py", line 918, in getaddrinfo
    for res in _socket.getaddrinfo(host, port, family, type, proto, flags):
socket.gaierror: [Errno 11004] getaddrinfo failed

During handling of the above exception, another exception occurred:

Traceback (most recent call last):
  File "C:\Users\питер\AppData\Local\Programs\Python\Python38\lib\site-packages\telegram\vendor\ptb_urllib3\urllib3\connectionpool.py", line 614, in urlopen
    httplib_response = self._make_request(conn, method, url,
  File "C:\Users\питер\AppData\Local\Programs\Python\Python38\lib\site-packages\telegram\vendor\ptb_urllib3\urllib3\connectionpool.py", line 360, in _make_request
    self._validate_conn(conn)
  File "C:\Users\питер\AppData\Local\Programs\Python\Python38\lib\site-packages\telegram\vendor\ptb_urllib3\urllib3\connectionpool.py", line 857, in _validate_conn
    super(HTTPSConnectionPool, self)._validate_conn(conn)
  File "C:\Users\питер\AppData\Local\Programs\Python\Python38\lib\site-packages\telegram\vendor\ptb_urllib3\urllib3\connectionpool.py", line 289, in _validate_conn
    conn.connect()
  File "C:\Users\питер\AppData\Local\Programs\Python\Python38\lib\site-packages\telegram\vendor\ptb_urllib3\urllib3\connection.py", line 284, in connect
    conn = self._new_conn()
  File "C:\Users\питер\AppData\Local\Programs\Python\Python38\lib\site-packages\telegram\vendor\ptb_urllib3\urllib3\contrib\socks.py", line 119, in _new_conn
    raise NewConnectionError(
telegram.vendor.ptb_urllib3.urllib3.exceptions.NewConnectionError: <telegram.vendor.ptb_urllib3.urllib3.contrib.socks.SOCKSHTTPSConnection object at 0x0000000004D1C430>: Failed to establish a new connection: [Errno 11004] getaddrinfo failed

During handling of the above exception, another exception occurred:

Traceback (most recent call last):
  File "C:\Users\питер\AppData\Local\Programs\Python\Python38\lib\site-packages\telegram\utils\request.py", line 259, in _request_wrapper
    resp = self._con_pool.request(*args, **kwargs)
  File "C:\Users\питер\AppData\Local\Programs\Python\Python38\lib\site-packages\telegram\vendor\ptb_urllib3\urllib3\request.py", line 68, in request
    return self.request_encode_body(method, url, fields=fields,
  File "C:\Users\питер\AppData\Local\Programs\Python\Python38\lib\site-packages\telegram\vendor\ptb_urllib3\urllib3\request.py", line 148, in request_encode_body
    return self.urlopen(method, url, **extra_kw)
  File "C:\Users\питер\AppData\Local\Programs\Python\Python38\lib\site-packages\telegram\vendor\ptb_urllib3\urllib3\poolmanager.py", line 244, in urlopen
    response = conn.urlopen(method, u.request_uri, **kw)
  File "C:\Users\питер\AppData\Local\Programs\Python\Python38\lib\site-packages\telegram\vendor\ptb_urllib3\urllib3\connectionpool.py", line 691, in urlopen
    return self.urlopen(method, url, body, headers, retries,
  File "C:\Users\питер\AppData\Local\Programs\Python\Python38\lib\site-packages\telegram\vendor\ptb_urllib3\urllib3\connectionpool.py", line 691, in urlopen
    return self.urlopen(method, url, body, headers, retries,
  File "C:\Users\питер\AppData\Local\Programs\Python\Python38\lib\site-packages\telegram\vendor\ptb_urllib3\urllib3\connectionpool.py", line 691, in urlopen
    return self.urlopen(method, url, body, headers, retries,
  File "C:\Users\питер\AppData\Local\Programs\Python\Python38\lib\site-packages\telegram\vendor\ptb_urllib3\urllib3\connectionpool.py", line 665, in urlopen
    retries = retries.increment(method, url, error=e, _pool=self,
  File "C:\Users\питер\AppData\Local\Programs\Python\Python38\lib\site-packages\telegram\vendor\ptb_urllib3\urllib3\util\retry.py", line 376, in increment
    raise MaxRetryError(_pool, url, error or ResponseError(cause))
telegram.vendor.ptb_urllib3.urllib3.exceptions.MaxRetryError: SOCKSHTTPSConnectionPool(host='api.telegram.org', port=443): Max retries exceeded with url: /bot1998874930:AAHSRnVPn6qTkHA0DGaLdtR17VQP4DxC0Ao/getUpdates (Caused by NewConnectionError('<telegram.vendor.ptb_urllib3.urllib3.contrib.socks.SOCKSHTTPSConnection object at 0x0000000004D1C430>: Failed to establish a new connection: [Errno 11004] getaddrinfo failed'))

The above exception was the direct cause of the following exception:

Traceback (most recent call last):
  File "C:\Users\питер\AppData\Local\Programs\Python\Python38\lib\site-packages\telegram\ext\updater.py", line 646, in _network_loop_retry
    if not action_cb():
  File "C:\Users\питер\AppData\Local\Programs\Python\Python38\lib\site-packages\telegram\ext\updater.py", line 597, in polling_action_cb
    updates = self.bot.get_updates(
  File "C:\Users\питер\AppData\Local\Programs\Python\Python38\lib\site-packages\telegram\ext\extbot.py", line 222, in get_updates
    updates = super().get_updates(
  File "C:\Users\питер\AppData\Local\Programs\Python\Python38\lib\site-packages\telegram\bot.py", line 130, in decorator
    result = func(*args, **kwargs)
  File "C:\Users\питер\AppData\Local\Programs\Python\Python38\lib\site-packages\telegram\bot.py", line 2861, in get_updates
    self._post(
  File "C:\Users\питер\AppData\Local\Programs\Python\Python38\lib\site-packages\telegram\bot.py", line 295, in _post
    return self.request.post(
  File "C:\Users\питер\AppData\Local\Programs\Python\Python38\lib\site-packages\telegram\utils\request.py", line 356, in post
    result = self._request_wrapper(
  File "C:\Users\питер\AppData\Local\Programs\Python\Python38\lib\site-packages\telegram\utils\request.py", line 265, in _request_wrapper
    raise NetworkError(f'urllib3 HTTPError {error}') from error
telegram.error.NetworkError: urllib3 HTTPError SOCKSHTTPSConnectionPool(host='api.telegram.org', port=443): Max retries exceeded with url: /bot1998874930:AAHSRnVPn6qTkHA0DGaLdtR17VQP4DxC0Ao/getUpdates (Caused by NewConnectionError('<telegram.vendor.ptb_urllib3.urllib3.contrib.socks.SOCKSHTTPSConnection object at 0x0000000004D1C430>: Failed to establish a new connection: [Errno 11004] getaddrinfo failed'))
